[2025-03-10T06:39:23.852+0000] {taskinstance.py:1159} INFO - Dependencies all met for dep_context=non-requeueable deps ti=<TaskInstance: stock_data_pipeline.update_stock_data scheduled__2025-03-10T05:30:00+00:00 [queued]>
[2025-03-10T06:39:23.860+0000] {taskinstance.py:1159} INFO - Dependencies all met for dep_context=requeueable deps ti=<TaskInstance: stock_data_pipeline.update_stock_data scheduled__2025-03-10T05:30:00+00:00 [queued]>
[2025-03-10T06:39:23.861+0000] {taskinstance.py:1361} INFO - Starting attempt 1 of 2
[2025-03-10T06:39:23.915+0000] {taskinstance.py:1382} INFO - Executing <Task(PythonOperator): update_stock_data> on 2025-03-10 05:30:00+00:00
[2025-03-10T06:39:23.922+0000] {standard_task_runner.py:57} INFO - Started process 1215 to run task
[2025-03-10T06:39:23.931+0000] {standard_task_runner.py:84} INFO - Running: ['airflow', 'tasks', 'run', 'stock_data_pipeline', 'update_stock_data', 'scheduled__2025-03-10T05:30:00+00:00', '--job-id', '53', '--raw', '--subdir', 'DAGS_FOLDER/stock_data_dag.py', '--cfg-path', '/tmp/tmptlbo24bl']
[2025-03-10T06:39:23.933+0000] {standard_task_runner.py:85} INFO - Job 53: Subtask update_stock_data
[2025-03-10T06:39:23.989+0000] {task_command.py:415} INFO - Running <TaskInstance: stock_data_pipeline.update_stock_data scheduled__2025-03-10T05:30:00+00:00 [running]> on host e700ec0e84b1
[2025-03-10T06:39:24.047+0000] {taskinstance.py:1660} INFO - Exporting env vars: AIRFLOW_CTX_DAG_OWNER='ekaterina' AIRFLOW_CTX_DAG_ID='stock_data_pipeline' AIRFLOW_CTX_TASK_ID='update_stock_data' AIRFLOW_CTX_EXECUTION_DATE='2025-03-10T05:30:00+00:00' AIRFLOW_CTX_TRY_NUMBER='1' AIRFLOW_CTX_DAG_RUN_ID='scheduled__2025-03-10T05:30:00+00:00'
[2025-03-10T06:39:24.083+0000] {taskinstance.py:1943} ERROR - Task failed with exception
Traceback (most recent call last):
  File "/home/airflow/.local/lib/python3.8/site-packages/airflow/operators/python.py", line 192, in execute
    return_value = self.execute_callable()
  File "/home/airflow/.local/lib/python3.8/site-packages/airflow/operators/python.py", line 209, in execute_callable
    return self.python_callable(*self.op_args, **self.op_kwargs)
  File "/opt/airflow/dags/stock_data_dag.py", line 23, in run_update
    subprocess.run(["docker", "exec", "stock_project-stock-fetcher", "python", "update_stock_data.py"], check=True)
  File "/usr/local/lib/python3.8/subprocess.py", line 516, in run
    raise CalledProcessError(retcode, process.args,
subprocess.CalledProcessError: Command '['docker', 'exec', 'stock_project-stock-fetcher', 'python', 'update_stock_data.py']' returned non-zero exit status 1.
[2025-03-10T06:39:24.100+0000] {taskinstance.py:1400} INFO - Marking task as UP_FOR_RETRY. dag_id=stock_data_pipeline, task_id=update_stock_data, execution_date=20250310T053000, start_date=20250310T063923, end_date=20250310T063924
[2025-03-10T06:39:24.108+0000] {standard_task_runner.py:104} ERROR - Failed to execute job 53 for task update_stock_data (Command '['docker', 'exec', 'stock_project-stock-fetcher', 'python', 'update_stock_data.py']' returned non-zero exit status 1.; 1215)
[2025-03-10T06:39:24.154+0000] {local_task_job_runner.py:228} INFO - Task exited with return code 1
[2025-03-10T06:39:24.173+0000] {taskinstance.py:2784} INFO - 0 downstream tasks scheduled from follow-on schedule check
