[2025-03-10T08:03:55.827+0000] {taskinstance.py:1159} INFO - Dependencies all met for dep_context=non-requeueable deps ti=<TaskInstance: stock_data_pipeline.update_stock_data manual__2025-03-10T07:56:44.016983+00:00 [queued]>
[2025-03-10T08:03:55.834+0000] {taskinstance.py:1159} INFO - Dependencies all met for dep_context=requeueable deps ti=<TaskInstance: stock_data_pipeline.update_stock_data manual__2025-03-10T07:56:44.016983+00:00 [queued]>
[2025-03-10T08:03:55.834+0000] {taskinstance.py:1361} INFO - Starting attempt 3 of 3
[2025-03-10T08:03:55.915+0000] {taskinstance.py:1382} INFO - Executing <Task(PythonOperator): update_stock_data> on 2025-03-10 07:56:44.016983+00:00
[2025-03-10T08:03:55.920+0000] {standard_task_runner.py:57} INFO - Started process 159 to run task
[2025-03-10T08:03:55.923+0000] {standard_task_runner.py:84} INFO - Running: ['airflow', 'tasks', 'run', 'stock_data_pipeline', 'update_stock_data', 'manual__2025-03-10T07:56:44.016983+00:00', '--job-id', '70', '--raw', '--subdir', 'DAGS_FOLDER/stock_data_dag.py', '--cfg-path', '/tmp/tmp4sl5qkqc']
[2025-03-10T08:03:55.925+0000] {standard_task_runner.py:85} INFO - Job 70: Subtask update_stock_data
[2025-03-10T08:03:55.967+0000] {task_command.py:415} INFO - Running <TaskInstance: stock_data_pipeline.update_stock_data manual__2025-03-10T07:56:44.016983+00:00 [running]> on host 8fcd4e749019
[2025-03-10T08:03:56.024+0000] {taskinstance.py:1660} INFO - Exporting env vars: AIRFLOW_CTX_DAG_OWNER='ekaterina' AIRFLOW_CTX_DAG_ID='stock_data_pipeline' AIRFLOW_CTX_TASK_ID='update_stock_data' AIRFLOW_CTX_EXECUTION_DATE='2025-03-10T07:56:44.016983+00:00' AIRFLOW_CTX_TRY_NUMBER='3' AIRFLOW_CTX_DAG_RUN_ID='manual__2025-03-10T07:56:44.016983+00:00'
[2025-03-10T08:03:56.088+0000] {taskinstance.py:1943} ERROR - Task failed with exception
Traceback (most recent call last):
  File "/home/airflow/.local/lib/python3.8/site-packages/airflow/operators/python.py", line 192, in execute
    return_value = self.execute_callable()
  File "/home/airflow/.local/lib/python3.8/site-packages/airflow/operators/python.py", line 209, in execute_callable
    return self.python_callable(*self.op_args, **self.op_kwargs)
  File "/opt/airflow/dags/stock_data_dag.py", line 41, in run_update
    subprocess.run(["docker", "exec", "stock_project-stock-fetcher", "python", "update_stock_data.py"], check=True)
  File "/usr/local/lib/python3.8/subprocess.py", line 516, in run
    raise CalledProcessError(retcode, process.args,
subprocess.CalledProcessError: Command '['docker', 'exec', 'stock_project-stock-fetcher', 'python', 'update_stock_data.py']' returned non-zero exit status 1.
[2025-03-10T08:03:56.100+0000] {taskinstance.py:1400} INFO - Marking task as FAILED. dag_id=stock_data_pipeline, task_id=update_stock_data, execution_date=20250310T075644, start_date=20250310T080355, end_date=20250310T080356
[2025-03-10T08:03:56.110+0000] {standard_task_runner.py:104} ERROR - Failed to execute job 70 for task update_stock_data (Command '['docker', 'exec', 'stock_project-stock-fetcher', 'python', 'update_stock_data.py']' returned non-zero exit status 1.; 159)
[2025-03-10T08:03:56.145+0000] {local_task_job_runner.py:228} INFO - Task exited with return code 1
[2025-03-10T08:03:56.162+0000] {taskinstance.py:2784} INFO - 0 downstream tasks scheduled from follow-on schedule check
