[2025-03-10T13:05:05.529+0000] {taskinstance.py:1159} INFO - Dependencies all met for dep_context=non-requeueable deps ti=<TaskInstance: stock_data_pipeline.update_stock_data scheduled__2025-03-10T12:30:00+00:00 [queued]>
[2025-03-10T13:05:05.533+0000] {taskinstance.py:1159} INFO - Dependencies all met for dep_context=requeueable deps ti=<TaskInstance: stock_data_pipeline.update_stock_data scheduled__2025-03-10T12:30:00+00:00 [queued]>
[2025-03-10T13:05:05.533+0000] {taskinstance.py:1361} INFO - Starting attempt 2 of 2
[2025-03-10T13:05:05.577+0000] {taskinstance.py:1382} INFO - Executing <Task(PythonOperator): update_stock_data> on 2025-03-10 12:30:00+00:00
[2025-03-10T13:05:05.581+0000] {standard_task_runner.py:57} INFO - Started process 745 to run task
[2025-03-10T13:05:05.584+0000] {standard_task_runner.py:84} INFO - Running: ['airflow', 'tasks', 'run', 'stock_data_pipeline', 'update_stock_data', 'scheduled__2025-03-10T12:30:00+00:00', '--job-id', '97', '--raw', '--subdir', 'DAGS_FOLDER/stock_data_dag.py', '--cfg-path', '/tmp/tmpogoyc4e2']
[2025-03-10T13:05:05.585+0000] {standard_task_runner.py:85} INFO - Job 97: Subtask update_stock_data
[2025-03-10T13:05:05.645+0000] {task_command.py:415} INFO - Running <TaskInstance: stock_data_pipeline.update_stock_data scheduled__2025-03-10T12:30:00+00:00 [running]> on host 8fcd4e749019
[2025-03-10T13:05:05.706+0000] {taskinstance.py:1660} INFO - Exporting env vars: AIRFLOW_CTX_DAG_OWNER='ekaterina' AIRFLOW_CTX_DAG_ID='stock_data_pipeline' AIRFLOW_CTX_TASK_ID='update_stock_data' AIRFLOW_CTX_EXECUTION_DATE='2025-03-10T12:30:00+00:00' AIRFLOW_CTX_TRY_NUMBER='2' AIRFLOW_CTX_DAG_RUN_ID='scheduled__2025-03-10T12:30:00+00:00'
[2025-03-10T13:05:05.744+0000] {logging_mixin.py:151} INFO - STDOUT: 
[2025-03-10T13:05:05.745+0000] {logging_mixin.py:151} INFO - STDERR: Cannot connect to the Docker daemon at unix:///var/run/docker.sock. Is the docker daemon running?
[2025-03-10T13:05:05.745+0000] {logging_mixin.py:151} INFO - Exit Code: 1
[2025-03-10T13:05:05.745+0000] {taskinstance.py:1943} ERROR - Task failed with exception
Traceback (most recent call last):
  File "/home/airflow/.local/lib/python3.8/site-packages/airflow/operators/python.py", line 192, in execute
    return_value = self.execute_callable()
  File "/home/airflow/.local/lib/python3.8/site-packages/airflow/operators/python.py", line 209, in execute_callable
    return self.python_callable(*self.op_args, **self.op_kwargs)
  File "/opt/airflow/dags/stock_data_dag.py", line 34, in run_update
    raise Exception(f"Update stock data failed with exit code {result.returncode}: {result.stderr}")
Exception: Update stock data failed with exit code 1: Cannot connect to the Docker daemon at unix:///var/run/docker.sock. Is the docker daemon running?

[2025-03-10T13:05:05.754+0000] {taskinstance.py:1400} INFO - Marking task as FAILED. dag_id=stock_data_pipeline, task_id=update_stock_data, execution_date=20250310T123000, start_date=20250310T130505, end_date=20250310T130505
[2025-03-10T13:05:05.759+0000] {standard_task_runner.py:104} ERROR - Failed to execute job 97 for task update_stock_data (Update stock data failed with exit code 1: Cannot connect to the Docker daemon at unix:///var/run/docker.sock. Is the docker daemon running?
; 745)
[2025-03-10T13:05:05.768+0000] {local_task_job_runner.py:228} INFO - Task exited with return code 1
[2025-03-10T13:05:05.783+0000] {taskinstance.py:2784} INFO - 0 downstream tasks scheduled from follow-on schedule check
