[2025-03-10T13:00:02.546+0000] {taskinstance.py:1159} INFO - Dependencies all met for dep_context=non-requeueable deps ti=<TaskInstance: stock_data_pipeline.update_stock_data scheduled__2025-03-10T12:30:00+00:00 [queued]>
[2025-03-10T13:00:02.550+0000] {taskinstance.py:1159} INFO - Dependencies all met for dep_context=requeueable deps ti=<TaskInstance: stock_data_pipeline.update_stock_data scheduled__2025-03-10T12:30:00+00:00 [queued]>
[2025-03-10T13:00:02.550+0000] {taskinstance.py:1361} INFO - Starting attempt 1 of 2
[2025-03-10T13:00:02.599+0000] {taskinstance.py:1382} INFO - Executing <Task(PythonOperator): update_stock_data> on 2025-03-10 12:30:00+00:00
[2025-03-10T13:00:02.603+0000] {standard_task_runner.py:57} INFO - Started process 714 to run task
[2025-03-10T13:00:02.609+0000] {standard_task_runner.py:84} INFO - Running: ['airflow', 'tasks', 'run', 'stock_data_pipeline', 'update_stock_data', 'scheduled__2025-03-10T12:30:00+00:00', '--job-id', '96', '--raw', '--subdir', 'DAGS_FOLDER/stock_data_dag.py', '--cfg-path', '/tmp/tmpez096obw']
[2025-03-10T13:00:02.611+0000] {standard_task_runner.py:85} INFO - Job 96: Subtask update_stock_data
[2025-03-10T13:00:02.666+0000] {task_command.py:415} INFO - Running <TaskInstance: stock_data_pipeline.update_stock_data scheduled__2025-03-10T12:30:00+00:00 [running]> on host 8fcd4e749019
[2025-03-10T13:00:02.719+0000] {taskinstance.py:1660} INFO - Exporting env vars: AIRFLOW_CTX_DAG_OWNER='ekaterina' AIRFLOW_CTX_DAG_ID='stock_data_pipeline' AIRFLOW_CTX_TASK_ID='update_stock_data' AIRFLOW_CTX_EXECUTION_DATE='2025-03-10T12:30:00+00:00' AIRFLOW_CTX_TRY_NUMBER='1' AIRFLOW_CTX_DAG_RUN_ID='scheduled__2025-03-10T12:30:00+00:00'
[2025-03-10T13:00:02.759+0000] {logging_mixin.py:151} INFO - STDOUT: 
[2025-03-10T13:00:02.759+0000] {logging_mixin.py:151} INFO - STDERR: Cannot connect to the Docker daemon at unix:///var/run/docker.sock. Is the docker daemon running?
[2025-03-10T13:00:02.759+0000] {logging_mixin.py:151} INFO - Exit Code: 1
[2025-03-10T13:00:02.760+0000] {taskinstance.py:1943} ERROR - Task failed with exception
Traceback (most recent call last):
  File "/home/airflow/.local/lib/python3.8/site-packages/airflow/operators/python.py", line 192, in execute
    return_value = self.execute_callable()
  File "/home/airflow/.local/lib/python3.8/site-packages/airflow/operators/python.py", line 209, in execute_callable
    return self.python_callable(*self.op_args, **self.op_kwargs)
  File "/opt/airflow/dags/stock_data_dag.py", line 34, in run_update
    raise Exception(f"Update stock data failed with exit code {result.returncode}: {result.stderr}")
Exception: Update stock data failed with exit code 1: Cannot connect to the Docker daemon at unix:///var/run/docker.sock. Is the docker daemon running?

[2025-03-10T13:00:02.770+0000] {taskinstance.py:1400} INFO - Marking task as UP_FOR_RETRY. dag_id=stock_data_pipeline, task_id=update_stock_data, execution_date=20250310T123000, start_date=20250310T130002, end_date=20250310T130002
[2025-03-10T13:00:02.778+0000] {standard_task_runner.py:104} ERROR - Failed to execute job 96 for task update_stock_data (Update stock data failed with exit code 1: Cannot connect to the Docker daemon at unix:///var/run/docker.sock. Is the docker daemon running?
; 714)
[2025-03-10T13:00:02.795+0000] {local_task_job_runner.py:228} INFO - Task exited with return code 1
[2025-03-10T13:00:02.808+0000] {taskinstance.py:2784} INFO - 0 downstream tasks scheduled from follow-on schedule check
