[2025-03-09T13:17:05.141+0000] {taskinstance.py:1159} INFO - Dependencies all met for dep_context=non-requeueable deps ti=<TaskInstance: stock_data_pipeline.backfill_new_companies manual__2025-03-08T21:00:21.679054+00:00 [queued]>
[2025-03-09T13:17:05.352+0000] {taskinstance.py:1159} INFO - Dependencies all met for dep_context=requeueable deps ti=<TaskInstance: stock_data_pipeline.backfill_new_companies manual__2025-03-08T21:00:21.679054+00:00 [queued]>
[2025-03-09T13:17:05.353+0000] {taskinstance.py:1361} INFO - Starting attempt 2 of 2
[2025-03-09T13:17:05.370+0000] {taskinstance.py:1382} INFO - Executing <Task(PythonOperator): backfill_new_companies> on 2025-03-08 21:00:21.679054+00:00
[2025-03-09T13:17:05.386+0000] {standard_task_runner.py:57} INFO - Started process 65 to run task
[2025-03-09T13:17:05.396+0000] {standard_task_runner.py:84} INFO - Running: ['airflow', 'tasks', 'run', 'stock_data_pipeline', 'backfill_new_companies', 'manual__2025-03-08T21:00:21.679054+00:00', '--job-id', '18', '--raw', '--subdir', 'DAGS_FOLDER/stock_data_dag.py', '--cfg-path', '/tmp/tmpwa78fgxr']
[2025-03-09T13:17:05.399+0000] {standard_task_runner.py:85} INFO - Job 18: Subtask backfill_new_companies
[2025-03-09T13:17:05.467+0000] {task_command.py:415} INFO - Running <TaskInstance: stock_data_pipeline.backfill_new_companies manual__2025-03-08T21:00:21.679054+00:00 [running]> on host 438b0c3d734b
[2025-03-09T13:17:06.210+0000] {taskinstance.py:1660} INFO - Exporting env vars: AIRFLOW_CTX_DAG_OWNER='ekaterina' AIRFLOW_CTX_DAG_ID='stock_data_pipeline' AIRFLOW_CTX_TASK_ID='backfill_new_companies' AIRFLOW_CTX_EXECUTION_DATE='2025-03-08T21:00:21.679054+00:00' AIRFLOW_CTX_TRY_NUMBER='2' AIRFLOW_CTX_DAG_RUN_ID='manual__2025-03-08T21:00:21.679054+00:00'
[2025-03-09T13:17:06.447+0000] {taskinstance.py:1943} ERROR - Task failed with exception
Traceback (most recent call last):
  File "/home/airflow/.local/lib/python3.8/site-packages/airflow/operators/python.py", line 192, in execute
    return_value = self.execute_callable()
  File "/home/airflow/.local/lib/python3.8/site-packages/airflow/operators/python.py", line 209, in execute_callable
    return self.python_callable(*self.op_args, **self.op_kwargs)
  File "/opt/airflow/dags/stock_data_dag.py", line 23, in run_backfill
    subprocess.run(["docker", "exec", "-it", "stock_project-stock-fetcher", "python", "backfill_stock_data.py"], check=True)
  File "/usr/local/lib/python3.8/subprocess.py", line 516, in run
    raise CalledProcessError(retcode, process.args,
subprocess.CalledProcessError: Command '['docker', 'exec', '-it', 'stock_project-stock-fetcher', 'python', 'backfill_stock_data.py']' returned non-zero exit status 1.
[2025-03-09T13:17:06.511+0000] {taskinstance.py:1400} INFO - Marking task as FAILED. dag_id=stock_data_pipeline, task_id=backfill_new_companies, execution_date=20250308T210021, start_date=20250309T131705, end_date=20250309T131706
[2025-03-09T13:17:06.524+0000] {standard_task_runner.py:104} ERROR - Failed to execute job 18 for task backfill_new_companies (Command '['docker', 'exec', '-it', 'stock_project-stock-fetcher', 'python', 'backfill_stock_data.py']' returned non-zero exit status 1.; 65)
[2025-03-09T13:17:06.584+0000] {local_task_job_runner.py:228} INFO - Task exited with return code 1
[2025-03-09T13:17:06.645+0000] {taskinstance.py:2784} INFO - 0 downstream tasks scheduled from follow-on schedule check
