[2025-03-09T16:12:30.263+0000] {taskinstance.py:1159} INFO - Dependencies all met for dep_context=non-requeueable deps ti=<TaskInstance: stock_data_pipeline.backfill_new_companies scheduled__2025-03-07T20:00:00+00:00 [queued]>
[2025-03-09T16:12:30.269+0000] {taskinstance.py:1159} INFO - Dependencies all met for dep_context=requeueable deps ti=<TaskInstance: stock_data_pipeline.backfill_new_companies scheduled__2025-03-07T20:00:00+00:00 [queued]>
[2025-03-09T16:12:30.269+0000] {taskinstance.py:1361} INFO - Starting attempt 1 of 2
[2025-03-09T16:12:30.279+0000] {taskinstance.py:1382} INFO - Executing <Task(PythonOperator): backfill_new_companies> on 2025-03-07 20:00:00+00:00
[2025-03-09T16:12:30.288+0000] {standard_task_runner.py:57} INFO - Started process 77 to run task
[2025-03-09T16:12:30.295+0000] {standard_task_runner.py:84} INFO - Running: ['airflow', 'tasks', 'run', 'stock_data_pipeline', 'backfill_new_companies', 'scheduled__2025-03-07T20:00:00+00:00', '--job-id', '2', '--raw', '--subdir', 'DAGS_FOLDER/stock_data_dag.py', '--cfg-path', '/tmp/tmpq1t2c0aq']
[2025-03-09T16:12:30.297+0000] {standard_task_runner.py:85} INFO - Job 2: Subtask backfill_new_companies
[2025-03-09T16:12:30.480+0000] {task_command.py:415} INFO - Running <TaskInstance: stock_data_pipeline.backfill_new_companies scheduled__2025-03-07T20:00:00+00:00 [running]> on host e700ec0e84b1
[2025-03-09T16:12:30.536+0000] {taskinstance.py:1660} INFO - Exporting env vars: AIRFLOW_CTX_DAG_OWNER='ekaterina' AIRFLOW_CTX_DAG_ID='stock_data_pipeline' AIRFLOW_CTX_TASK_ID='backfill_new_companies' AIRFLOW_CTX_EXECUTION_DATE='2025-03-07T20:00:00+00:00' AIRFLOW_CTX_TRY_NUMBER='1' AIRFLOW_CTX_DAG_RUN_ID='scheduled__2025-03-07T20:00:00+00:00'
[2025-03-09T16:12:30.971+0000] {taskinstance.py:1943} ERROR - Task failed with exception
Traceback (most recent call last):
  File "/home/airflow/.local/lib/python3.8/site-packages/airflow/operators/python.py", line 192, in execute
    return_value = self.execute_callable()
  File "/home/airflow/.local/lib/python3.8/site-packages/airflow/operators/python.py", line 209, in execute_callable
    return self.python_callable(*self.op_args, **self.op_kwargs)
  File "/opt/airflow/dags/stock_data_dag.py", line 23, in run_backfill
    subprocess.run(["docker", "exec", "-it", "stock_project-stock-fetcher", "python", "backfill_stock_data.py"], check=True)
  File "/usr/local/lib/python3.8/subprocess.py", line 516, in run
    raise CalledProcessError(retcode, process.args,
subprocess.CalledProcessError: Command '['docker', 'exec', '-it', 'stock_project-stock-fetcher', 'python', 'backfill_stock_data.py']' returned non-zero exit status 1.
[2025-03-09T16:12:30.984+0000] {taskinstance.py:1400} INFO - Marking task as UP_FOR_RETRY. dag_id=stock_data_pipeline, task_id=backfill_new_companies, execution_date=20250307T200000, start_date=20250309T161230, end_date=20250309T161230
[2025-03-09T16:12:30.996+0000] {standard_task_runner.py:104} ERROR - Failed to execute job 2 for task backfill_new_companies (Command '['docker', 'exec', '-it', 'stock_project-stock-fetcher', 'python', 'backfill_stock_data.py']' returned non-zero exit status 1.; 77)
[2025-03-09T16:12:31.032+0000] {local_task_job_runner.py:228} INFO - Task exited with return code 1
[2025-03-09T16:12:31.052+0000] {taskinstance.py:2784} INFO - 0 downstream tasks scheduled from follow-on schedule check
