[2025-03-10T09:35:04.668+0000] {taskinstance.py:1159} INFO - Dependencies all met for dep_context=non-requeueable deps ti=<TaskInstance: stock_data_pipeline.update_stock_data scheduled__2025-03-10T09:00:00+00:00 [queued]>
[2025-03-10T09:35:04.710+0000] {taskinstance.py:1159} INFO - Dependencies all met for dep_context=requeueable deps ti=<TaskInstance: stock_data_pipeline.update_stock_data scheduled__2025-03-10T09:00:00+00:00 [queued]>
[2025-03-10T09:35:04.710+0000] {taskinstance.py:1361} INFO - Starting attempt 2 of 2
[2025-03-10T09:35:04.717+0000] {taskinstance.py:1382} INFO - Executing <Task(PythonOperator): update_stock_data> on 2025-03-10 09:00:00+00:00
[2025-03-10T09:35:04.721+0000] {standard_task_runner.py:57} INFO - Started process 276 to run task
[2025-03-10T09:35:04.722+0000] {standard_task_runner.py:84} INFO - Running: ['airflow', 'tasks', 'run', 'stock_data_pipeline', 'update_stock_data', 'scheduled__2025-03-10T09:00:00+00:00', '--job-id', '83', '--raw', '--subdir', 'DAGS_FOLDER/stock_data_dag.py', '--cfg-path', '/tmp/tmpojxtqngr']
[2025-03-10T09:35:04.724+0000] {standard_task_runner.py:85} INFO - Job 83: Subtask update_stock_data
[2025-03-10T09:35:04.773+0000] {task_command.py:415} INFO - Running <TaskInstance: stock_data_pipeline.update_stock_data scheduled__2025-03-10T09:00:00+00:00 [running]> on host 8fcd4e749019
[2025-03-10T09:35:04.826+0000] {taskinstance.py:1660} INFO - Exporting env vars: AIRFLOW_CTX_DAG_OWNER='ekaterina' AIRFLOW_CTX_DAG_ID='stock_data_pipeline' AIRFLOW_CTX_TASK_ID='update_stock_data' AIRFLOW_CTX_EXECUTION_DATE='2025-03-10T09:00:00+00:00' AIRFLOW_CTX_TRY_NUMBER='2' AIRFLOW_CTX_DAG_RUN_ID='scheduled__2025-03-10T09:00:00+00:00'
[2025-03-10T09:35:04.854+0000] {logging_mixin.py:151} INFO - STDOUT: 
[2025-03-10T09:35:04.854+0000] {logging_mixin.py:151} INFO - STDERR: Cannot connect to the Docker daemon at unix:///var/run/docker.sock. Is the docker daemon running?
[2025-03-10T09:35:04.854+0000] {logging_mixin.py:151} INFO - Exit Code: 1
[2025-03-10T09:35:04.855+0000] {taskinstance.py:1943} ERROR - Task failed with exception
Traceback (most recent call last):
  File "/home/airflow/.local/lib/python3.8/site-packages/airflow/operators/python.py", line 192, in execute
    return_value = self.execute_callable()
  File "/home/airflow/.local/lib/python3.8/site-packages/airflow/operators/python.py", line 209, in execute_callable
    return self.python_callable(*self.op_args, **self.op_kwargs)
  File "/opt/airflow/dags/stock_data_dag.py", line 34, in run_update
    raise Exception(f"Update stock data failed with exit code {result.returncode}: {result.stderr}")
Exception: Update stock data failed with exit code 1: Cannot connect to the Docker daemon at unix:///var/run/docker.sock. Is the docker daemon running?

[2025-03-10T09:35:04.862+0000] {taskinstance.py:1400} INFO - Marking task as FAILED. dag_id=stock_data_pipeline, task_id=update_stock_data, execution_date=20250310T090000, start_date=20250310T093504, end_date=20250310T093504
[2025-03-10T09:35:04.869+0000] {standard_task_runner.py:104} ERROR - Failed to execute job 83 for task update_stock_data (Update stock data failed with exit code 1: Cannot connect to the Docker daemon at unix:///var/run/docker.sock. Is the docker daemon running?
; 276)
[2025-03-10T09:35:04.877+0000] {local_task_job_runner.py:228} INFO - Task exited with return code 1
[2025-03-10T09:35:04.887+0000] {taskinstance.py:2784} INFO - 0 downstream tasks scheduled from follow-on schedule check
