[2025-03-08T20:56:01.601+0000] {taskinstance.py:1159} INFO - Dependencies all met for dep_context=non-requeueable deps ti=<TaskInstance: stock_data_pipeline.backfill_new_companies manual__2025-03-08T20:50:57.679166+00:00 [queued]>
[2025-03-08T20:56:01.648+0000] {taskinstance.py:1159} INFO - Dependencies all met for dep_context=requeueable deps ti=<TaskInstance: stock_data_pipeline.backfill_new_companies manual__2025-03-08T20:50:57.679166+00:00 [queued]>
[2025-03-08T20:56:01.649+0000] {taskinstance.py:1361} INFO - Starting attempt 2 of 2
[2025-03-08T20:56:01.656+0000] {taskinstance.py:1382} INFO - Executing <Task(PythonOperator): backfill_new_companies> on 2025-03-08 20:50:57.679166+00:00
[2025-03-08T20:56:01.659+0000] {standard_task_runner.py:57} INFO - Started process 283 to run task
[2025-03-08T20:56:01.661+0000] {standard_task_runner.py:84} INFO - Running: ['airflow', 'tasks', 'run', 'stock_data_pipeline', 'backfill_new_companies', 'manual__2025-03-08T20:50:57.679166+00:00', '--job-id', '15', '--raw', '--subdir', 'DAGS_FOLDER/stock_data_dag.py', '--cfg-path', '/tmp/tmp2sh3rhtm']
[2025-03-08T20:56:01.662+0000] {standard_task_runner.py:85} INFO - Job 15: Subtask backfill_new_companies
[2025-03-08T20:56:01.717+0000] {task_command.py:415} INFO - Running <TaskInstance: stock_data_pipeline.backfill_new_companies manual__2025-03-08T20:50:57.679166+00:00 [running]> on host 438b0c3d734b
[2025-03-08T20:56:01.781+0000] {taskinstance.py:1660} INFO - Exporting env vars: AIRFLOW_CTX_DAG_OWNER='ekaterina' AIRFLOW_CTX_DAG_ID='stock_data_pipeline' AIRFLOW_CTX_TASK_ID='backfill_new_companies' AIRFLOW_CTX_EXECUTION_DATE='2025-03-08T20:50:57.679166+00:00' AIRFLOW_CTX_TRY_NUMBER='2' AIRFLOW_CTX_DAG_RUN_ID='manual__2025-03-08T20:50:57.679166+00:00'
[2025-03-08T20:56:01.817+0000] {taskinstance.py:1943} ERROR - Task failed with exception
Traceback (most recent call last):
  File "/home/airflow/.local/lib/python3.8/site-packages/airflow/operators/python.py", line 192, in execute
    return_value = self.execute_callable()
  File "/home/airflow/.local/lib/python3.8/site-packages/airflow/operators/python.py", line 209, in execute_callable
    return self.python_callable(*self.op_args, **self.op_kwargs)
  File "/opt/airflow/dags/stock_data_dag.py", line 23, in run_backfill
    subprocess.run(["docker", "exec", "-it", "stock_project-stock-fetcher", "python", "backfill_stock_data.py"], check=True)
  File "/usr/local/lib/python3.8/subprocess.py", line 516, in run
    raise CalledProcessError(retcode, process.args,
subprocess.CalledProcessError: Command '['docker', 'exec', '-it', 'stock_project-stock-fetcher', 'python', 'backfill_stock_data.py']' returned non-zero exit status 1.
[2025-03-08T20:56:01.828+0000] {taskinstance.py:1400} INFO - Marking task as FAILED. dag_id=stock_data_pipeline, task_id=backfill_new_companies, execution_date=20250308T205057, start_date=20250308T205601, end_date=20250308T205601
[2025-03-08T20:56:01.837+0000] {standard_task_runner.py:104} ERROR - Failed to execute job 15 for task backfill_new_companies (Command '['docker', 'exec', '-it', 'stock_project-stock-fetcher', 'python', 'backfill_stock_data.py']' returned non-zero exit status 1.; 283)
[2025-03-08T20:56:01.842+0000] {local_task_job_runner.py:228} INFO - Task exited with return code 1
[2025-03-08T20:56:01.859+0000] {taskinstance.py:2784} INFO - 0 downstream tasks scheduled from follow-on schedule check
