[2025-03-10T08:35:03.980+0000] {taskinstance.py:1159} INFO - Dependencies all met for dep_context=non-requeueable deps ti=<TaskInstance: stock_data_pipeline.update_stock_data scheduled__2025-03-10T08:00:00+00:00 [queued]>
[2025-03-10T08:35:03.984+0000] {taskinstance.py:1159} INFO - Dependencies all met for dep_context=requeueable deps ti=<TaskInstance: stock_data_pipeline.update_stock_data scheduled__2025-03-10T08:00:00+00:00 [queued]>
[2025-03-10T08:35:03.984+0000] {taskinstance.py:1361} INFO - Starting attempt 2 of 2
[2025-03-10T08:35:04.031+0000] {taskinstance.py:1382} INFO - Executing <Task(PythonOperator): update_stock_data> on 2025-03-10 08:00:00+00:00
[2025-03-10T08:35:04.035+0000] {standard_task_runner.py:57} INFO - Started process 129 to run task
[2025-03-10T08:35:04.038+0000] {standard_task_runner.py:84} INFO - Running: ['airflow', 'tasks', 'run', 'stock_data_pipeline', 'update_stock_data', 'scheduled__2025-03-10T08:00:00+00:00', '--job-id', '79', '--raw', '--subdir', 'DAGS_FOLDER/stock_data_dag.py', '--cfg-path', '/tmp/tmpr9yuccrp']
[2025-03-10T08:35:04.041+0000] {standard_task_runner.py:85} INFO - Job 79: Subtask update_stock_data
[2025-03-10T08:35:04.101+0000] {task_command.py:415} INFO - Running <TaskInstance: stock_data_pipeline.update_stock_data scheduled__2025-03-10T08:00:00+00:00 [running]> on host 8fcd4e749019
[2025-03-10T08:35:04.150+0000] {taskinstance.py:1660} INFO - Exporting env vars: AIRFLOW_CTX_DAG_OWNER='ekaterina' AIRFLOW_CTX_DAG_ID='stock_data_pipeline' AIRFLOW_CTX_TASK_ID='update_stock_data' AIRFLOW_CTX_EXECUTION_DATE='2025-03-10T08:00:00+00:00' AIRFLOW_CTX_TRY_NUMBER='2' AIRFLOW_CTX_DAG_RUN_ID='scheduled__2025-03-10T08:00:00+00:00'
[2025-03-10T08:35:04.245+0000] {logging_mixin.py:151} INFO - STDOUT: 
[2025-03-10T08:35:04.246+0000] {logging_mixin.py:151} INFO - STDERR: Cannot connect to the Docker daemon at unix:///var/run/docker.sock. Is the docker daemon running?
[2025-03-10T08:35:04.246+0000] {logging_mixin.py:151} INFO - Exit Code: 1
[2025-03-10T08:35:04.246+0000] {taskinstance.py:1943} ERROR - Task failed with exception
Traceback (most recent call last):
  File "/home/airflow/.local/lib/python3.8/site-packages/airflow/operators/python.py", line 192, in execute
    return_value = self.execute_callable()
  File "/home/airflow/.local/lib/python3.8/site-packages/airflow/operators/python.py", line 209, in execute_callable
    return self.python_callable(*self.op_args, **self.op_kwargs)
  File "/opt/airflow/dags/stock_data_dag.py", line 34, in run_update
    raise Exception(f"Update stock data failed with exit code {result.returncode}: {result.stderr}")
Exception: Update stock data failed with exit code 1: Cannot connect to the Docker daemon at unix:///var/run/docker.sock. Is the docker daemon running?

[2025-03-10T08:35:04.259+0000] {taskinstance.py:1400} INFO - Marking task as FAILED. dag_id=stock_data_pipeline, task_id=update_stock_data, execution_date=20250310T080000, start_date=20250310T083503, end_date=20250310T083504
[2025-03-10T08:35:04.269+0000] {standard_task_runner.py:104} ERROR - Failed to execute job 79 for task update_stock_data (Update stock data failed with exit code 1: Cannot connect to the Docker daemon at unix:///var/run/docker.sock. Is the docker daemon running?
; 129)
[2025-03-10T08:35:04.309+0000] {local_task_job_runner.py:228} INFO - Task exited with return code 1
[2025-03-10T08:35:04.319+0000] {taskinstance.py:2784} INFO - 0 downstream tasks scheduled from follow-on schedule check
