[2025-03-08T20:26:42.810+0000] {taskinstance.py:1159} INFO - Dependencies all met for dep_context=non-requeueable deps ti=<TaskInstance: stock_data_pipeline.backfill_new_companies manual__2025-03-08T20:26:40.872579+00:00 [queued]>
[2025-03-08T20:26:42.848+0000] {taskinstance.py:1159} INFO - Dependencies all met for dep_context=requeueable deps ti=<TaskInstance: stock_data_pipeline.backfill_new_companies manual__2025-03-08T20:26:40.872579+00:00 [queued]>
[2025-03-08T20:26:42.849+0000] {taskinstance.py:1361} INFO - Starting attempt 1 of 2
[2025-03-08T20:26:42.854+0000] {taskinstance.py:1382} INFO - Executing <Task(PythonOperator): backfill_new_companies> on 2025-03-08 20:26:40.872579+00:00
[2025-03-08T20:26:42.858+0000] {standard_task_runner.py:57} INFO - Started process 102 to run task
[2025-03-08T20:26:42.858+0000] {standard_task_runner.py:84} INFO - Running: ['airflow', 'tasks', 'run', 'stock_data_pipeline', 'backfill_new_companies', 'manual__2025-03-08T20:26:40.872579+00:00', '--job-id', '9', '--raw', '--subdir', 'DAGS_FOLDER/stock_data_dag.py', '--cfg-path', '/tmp/tmp6xz5bwuq']
[2025-03-08T20:26:42.860+0000] {standard_task_runner.py:85} INFO - Job 9: Subtask backfill_new_companies
[2025-03-08T20:26:42.966+0000] {task_command.py:415} INFO - Running <TaskInstance: stock_data_pipeline.backfill_new_companies manual__2025-03-08T20:26:40.872579+00:00 [running]> on host 438b0c3d734b
[2025-03-08T20:26:43.056+0000] {taskinstance.py:1660} INFO - Exporting env vars: AIRFLOW_CTX_DAG_OWNER='ekaterina' AIRFLOW_CTX_DAG_ID='stock_data_pipeline' AIRFLOW_CTX_TASK_ID='backfill_new_companies' AIRFLOW_CTX_EXECUTION_DATE='2025-03-08T20:26:40.872579+00:00' AIRFLOW_CTX_TRY_NUMBER='1' AIRFLOW_CTX_DAG_RUN_ID='manual__2025-03-08T20:26:40.872579+00:00'
[2025-03-08T20:26:43.104+0000] {taskinstance.py:1943} ERROR - Task failed with exception
Traceback (most recent call last):
  File "/home/airflow/.local/lib/python3.8/site-packages/airflow/operators/python.py", line 192, in execute
    return_value = self.execute_callable()
  File "/home/airflow/.local/lib/python3.8/site-packages/airflow/operators/python.py", line 209, in execute_callable
    return self.python_callable(*self.op_args, **self.op_kwargs)
  File "/opt/airflow/dags/stock_data_dag.py", line 23, in run_backfill
    subprocess.run(["docker", "exec", "-it", "stock_project-stock-fetcher", "python", "backfill_stock_data.py"], check=True)
  File "/usr/local/lib/python3.8/subprocess.py", line 516, in run
    raise CalledProcessError(retcode, process.args,
subprocess.CalledProcessError: Command '['docker', 'exec', '-it', 'stock_project-stock-fetcher', 'python', 'backfill_stock_data.py']' returned non-zero exit status 1.
[2025-03-08T20:26:43.113+0000] {taskinstance.py:1400} INFO - Marking task as UP_FOR_RETRY. dag_id=stock_data_pipeline, task_id=backfill_new_companies, execution_date=20250308T202640, start_date=20250308T202642, end_date=20250308T202643
[2025-03-08T20:26:43.120+0000] {standard_task_runner.py:104} ERROR - Failed to execute job 9 for task backfill_new_companies (Command '['docker', 'exec', '-it', 'stock_project-stock-fetcher', 'python', 'backfill_stock_data.py']' returned non-zero exit status 1.; 102)
[2025-03-08T20:26:43.133+0000] {local_task_job_runner.py:228} INFO - Task exited with return code 1
[2025-03-08T20:26:43.189+0000] {taskinstance.py:2784} INFO - 0 downstream tasks scheduled from follow-on schedule check
